Workbook

Sheet LOGIN
A1: LOGIN | B1: NUMERO | C1: INSCRIPTIONS | D1: PRENOM_VENDEUR | E1: NOM_VENDEUR
A2: pvt_tcg_0124 | B2: =VLOOKUP(A:A,Feuil2!A:B,2,) -> 782989910 | C2: =VLOOKUP(B:B,Feuil1!A:E,4,) -> 49 | D2: AMDY | E2: GUEYE
A3: pvt_tcg_0260 | B3: =VLOOKUP(A:A,Feuil2!A:B,2,) -> 787095594 | C3: =VLOOKUP(B:B,Feuil1!A:E,4,) -> 43 | D3: FATOU | E3: TAMBASSA
A4: pvt_tcg_0035 | B4: =VLOOKUP(A:A,Feuil2!A:B,2,) -> 781180981 | C4: =VLOOKUP(B:B,Feuil1!A:E,4,) -> 7 | D4: FAYE | E4: MOUHAMATH
A5: pvt_tcg_0331 | B5: =VLOOKUP(A:A,Feuil2!A:B,2,) -> 787095584 | C5: =VLOOKUP(B:B,Feuil1!A:E,4,) -> 9 | D5: SERIGNE FALLOU | E5: BITEYE
A6: pvt_smmc303 | B6: =VLOOKUP(A:A,Feuil2!A:B,2,) -> 786241266 | C6: =VLOOKUP(B:B,Feuil1!A:E,4,) -> 40 | D6: ASSANE | E6: DIOP
A7: pvt_smmc301 | B7: =VLOOKUP(A:A,Feuil2!A:B,2,) -> 786241255 | C7: =VLOOKUP(B:B,Feuil1!A:E,4,) -> 107 | D7: GAMOU | E7: NDIAYE
A8: pvt_smmc2695 | B8: =VLOOKUP(A:A,Feuil2!A:B,2,) -> 775812208 | C8: =VLOOKUP(B:B,Feuil1!A:E,4,) -> 42 | D8: MAYANE | E8: NDIM
A9: pvt_smmc2928 | B9: =VLOOKUP(A:A,Feuil2!A:B,2,) -> 789160174 | C9: =VLOOKUP(B:B,Feuil1!A:E,4,) -> 92 | D9: MODOU | E9: LO
A10: pvt_dfallf0182 | B10: =VLOOKUP(A:A,Feuil2!A:B,2,) -> 787655204 | C10: =VLOOKUP(B:B,Feuil1!A:E,4,) -> 107 | D10: ABDOULAYE | E10: DABO
A11: pvt_dfallf0271 | B11: =VLOOKUP(A:A,Feuil2!A:B,2,) -> 787657059 | C11: =VLOOKUP(B:B,Feuil1!A:E,4,) -> 47 | D11: AMY | E11: SAMB
A12: pvt_dfallf0272 | B12: =VLOOKUP(A:A,Feuil2!A:B,2,) -> 778528509 | C12: =VLOOKUP(B:B,Feuil1!A:E,4,) -> 110 | D12: AWA | E12: NDOUR
A13: pvt_dfallf0220 | B13: =VLOOKUP(A:A,Feuil2!A:B,2,) -> 787655222 | C13: =VLOOKUP(B:B,Feuil1!A:E,4,) -> 11 | D13: IBRAHIMA | E13: DIALLO
... A18: pvt_sosy134 | B18: =VLOOKUP(A:A,Feuil2!A:B,2,) -> 771883753 | C18: =VLOOKUP(B:B,Feuil1!A:E,4,) -> 3 | D18: ABDOULAYE | E18: DIALLO
A19: pvt_sosy0290 | B19: =VLOOKUP(A:A,Feuil2!A:B,2,) -> 775801980 | C19: 0 | D19: DIOR | E19: NDIAYE
A20: pvt_sosy165 | B20: =VLOOKUP(A:A,Feuil2!A:B,2,) -> 781596632 | C20: 0 | D20: KHADIDIATOU | E20: SOUARE
A21: pvt_sosy0560 | B21: =VLOOKUP(A:A,Feuil2!A:B,2,) -> 789167632 | C21: =VLOOKUP(B:B,Feuil1!A:E,4,) -> 3 | D21: MAHAMADOU | E21: SOW
A22: pvt_mwadk0290 | B22: =VLOOKUP(A:A,Feuil2!A:B,2,) -> 775810336 | C22: =VLOOKUP(B:B,Feuil1!A:E,4,) -> 1 | D22: FATOUMATA BINTA | E22: BA
A23: pvt_mwadk236 | B23: =VLOOKUP(A:A,Feuil2!A:B,2,) -> 778525987 | C23: =VLOOKUP(B:B,Feuil1!A:E,4,) -> 2 | D23: HAMADOU | E23: BALDE
A24: pvt_mwadk181 | B24: =VLOOKUP(A:A,Feuil2!A:B,2,) -> 772104981 | C24: =VLOOKUP(B:B,Feuil1!A:E,4,) -> 1 | D24: HAMADOU | E24: MBALLO
A25: pvt_mwadk194 | B25: =VLOOKUP(A:A,Feuil2!A:B,2,) -> 772107591 | C25: =VLOOKUP(B:B,Feuil1!A:E,4,) -> 2 | D25: MOUHAMADOU KALIDOU | E25: SOW

Sheet Feuil1
A1: NUMERO | B1: IU | C1: irreg | D1: Inscriptions | E1: LOGIN
A2: 710172779 | B2: 1 | C2: 0 | D2: =B2-C2 -> 1 | E2: =VLOOKUP(A:A,Feuil2!A:B,1,) -> #N/A
A3: 710339095 | B3: 1 | C3: 0 | D3: =B3-C3 -> 1 | E3: =VLOOKUP(A:A,Feuil2!A:B,1,) -> #N/A
A4: 710340984 | B4: 1 | C4: 0 | D4: =B4-C4 -> 1 | E4: =VLOOKUP(A:A,Feuil2!A:B,1,) -> #N/A
A5: 710349362 | B5: 4 | C5: 0 | D5: =B5-C5 -> 4 | E5: =VLOOKUP(A:A,Feuil2!A:B,1,) -> #N/A
A6: 710490371 | B6: 1 | C6: 0 | D6: =B6-C6 -> 1 | E6: =VLOOKUP(A:A,Feuil2!A:B,1,) -> #N/A
A7: 770100165 | B7: 3 | C7: 0 | D7: =B7-C7 -> 3 | E7: =VLOOKUP(A:A,Feuil2!A:B,1,) -> #N/A
A8: 770100218 | B8: 10 | C8: 0 | D8: =B8-C8 -> 10 | E8: =VLOOKUP(A:A,Feuil2!A:B,1,) -> #N/A
A9: 770100578 | B9: 8 | C9: 0 | D9: =B9-C9 -> 8 | E9: =VLOOKUP(A:A,Feuil2!A:B,1,) -> #N/A
A10: 770100732 | B10: 2 | C10: 0 | D10: =B10-C10 -> 2 | E10: =VLOOKUP(A:A,Feuil2!A:B,1,) -> #N/A
A11: 770100881 | B11: 1 | C11: 0 | D11: =B11-C11 -> 1 | E11: =VLOOKUP(A:A,Feuil2!A:B,1,) -> #N/A
A12: 770101925 | B12: 5 | C12: 0 | D12: =B12-C12 -> 5 | E12: =VLOOKUP(A:A,Feuil2!A:B,1,) -> 770101925
A13: 770102096 | B13: 1 | C13: 0 | D13: =B13-C13 -> 1 | E13: =VLOOKUP(A:A,Feuil2!A:B,1,) -> #N/A
... A2597: 789962619 | B2597: 1 | C2597: 0 | D2597: =B2597-C2597 -> 1 | E2597: =VLOOKUP(A:A,Feuil2!A:B,1,) -> 789962619
A2598: Total général | B2598: 16342 | C2598: 1664 | D2598: =B2598-C2598 -> 14678 | E2598: =VLOOKUP(A:A,Feuil2!A:B,1,) -> #N/A

Sheet Feuil2
A1: login_agent_recruteur | B1: msisdn_recruteur
A2: ext_diallo005056 | B2: 786230942
A3: userself | B3: 778919853
A4: 788885770 | B4: 788885770
A5: 789795760 | B5: 789795760
A6: pvt_bbatl1079 | B6: 789157375
A7: pvt_bbatl1294 | B7: 789169984
A8: pvt_smmc1083 | B8: 786195004
A9: pvt_skhol234 | B9: 777520552
A10: pvt_sfof0137 | B10: 776018863
A11: pvt_sfof0255 | B11: 789150430
A12: pvt_smmc2695 | B12: 775812208
A13: pvt_wac049 | B13: 786193840
A14: pvt_sls0018 | B14: 782992606
A15: pvt_teamc651 | B15: 786160142
A16: pvt_ibsen0090 | B16: 787656815
A17: b0153_ppo45 | B17: 786299124
... A54: pvt_sosy165 | B54: 781596632
A55: 770966012 | B55: 770966012
A56: pvt_sdiallo016 | B56: 775808708
A57: ext_dia2465 | B57: 787078339
A58: pvt_sosy109 | B58: 786164113
A59: pvt_mnvel_acvelra51 | B59: 771806416
A60: pvt_tndi_1415 | B60: 775812908
A61: ext_sarr3698 | B61: 786281614
A62: pvt_ofall1680 | B62: 789169875
A63: pvt_bndao_176 | B63: 782975451
A64: ext_ndao004010 | B64: 782971136
A65: ext_sow1286 | B65: 786281609
A66: pvt_cmtb0080 | B66: 787095824
A67: pvt_lgtel0310 | B67: 789616140
... A184: pvt_bbatl100 | B184: 786191922
A185: 779711704 | B185: 779711704
A186: pvt_mwadk173 | B186: 772105935
A187: pvt_ibsen0455 | B187: 787891825
A188: pvt_mbpling173 | B188: 776006374
A189: pvt_bbak_aked_ppo027 | B189: 786417070
A190: pvt_cmdb1814 | B190: 789160285
A191: ext_seck3214 | B191: 784537131
A192: pvt_tndi_933 | B192: 786199877
...
